<?xml version="1.0" ?>
<!-- =================================================================================== -->
<!-- |    This document was autogenerated by xacro from src/m2_metal_description/xacro/robot.xacro | -->
<!-- |    EDITING THIS FILE BY HAND IS NOT RECOMMENDED                                 | -->
<!-- =================================================================================== -->
<robot name="svan">
  <!-- base -->
  <!-- <xacro:property name="base_com_x" value="0.002585"/>
<xacro:property name="base_com_y" value="0.003221"/>
<xacro:property name="base_com_z" value="0.008796"/>
<xacro:property name="base_mass" value="5.428590"/>
<xacro:property name="base_ixx" value="0.028959"/>
<xacro:property name="base_ixy" value="-0.000021"/>
<xacro:property name="base_ixz" value="0.001591"/>
<xacro:property name="base_iyy" value="0.0601762"/>
<xacro:property name="base_iyz" value="0.000025"/>
<xacro:property name="base_izz" value="0.068516"/> -->
  <!-- without camera mount
<xacro:property name="base_com_x" value="-0.002656"/>
<xacro:property name="base_com_y" value="0.003430"/>
<xacro:property name="base_com_z" value="0.000860"/>
<xacro:property name="base_mass" value="5.016234"/>
<xacro:property name="base_ixx" value="0.023890"/>
<xacro:property name="base_ixy" value="-0.000506"/>
<xacro:property name="base_ixz" value="-0.001154"/>
<xacro:property name="base_iyy" value="0.053100"/>
<xacro:property name="base_iyz" value="-0.000013"/>
<xacro:property name="base_izz" value="0.065972"/> -->
  

  <!-- <xacro:include filename="$(find m2_description)/xacro/transmission.xacro"/> -->
  <material name="svan_black">
    <color rgba="0.0 0.0 0.0 1.0"/>
  </material>
  <material name="svan_blue">
    <color rgba="0.0 0.0 0.8 1.0"/>
  </material>
  <material name="svan_green">
    <color rgba="0.024 0.251 0.169 1.0"/>
  </material>
  <material name="svan_grey">
    <color rgba="0.5 0.5 0.5 1.0"/>
  </material>

  <mujoco>
    <compiler 
    meshdir="../meshes/"
    discardvisual="false"
    balanceinertia="true"
  />
  </mujoco>

  <link name="world"/>
  <joint name="floating_base" type="floating">
    <origin rpy="0 0 0" xyz="0 0 0"/>
    <parent link="world"/>
    <child link="base"/>
  </joint>

 <link name="base">
    <visual>
      <origin rpy="0 0 0" xyz="0 0 0"/>
      <geometry>
        <mesh filename="package://m2_metal_description/meshes/torso.STL" scale="1 1 1"/>
      </geometry>
      <material name="svan_green"/>
    </visual>
    <collision>
      <origin rpy="0 0 0" xyz="0 0 0"/>
      <geometry>
        <mesh filename="package://m2_metal_description/meshes/torso.STL"/>
      </geometry>
    </collision>
    <inertial>
      <origin rpy="0 0 0" xyz="0.00918208 -0.00133606 -0.00430117"/>
      <mass value="5.18596663"/>
      <inertia ixx="0.02220107" ixy="-0.00019966" ixz="-0.00048929" iyy="0.05026338" iyz="-1.273e-05" izz="0.06413613"/>
    </inertial>
  </link>
  <!-- hip_link-->
  <link name="FR_hip_link">
    <inertial>
      <origin rpy="0 0 0" xyz="0.04244851 -0.07733848 0.00084768"/>
      <mass value="1.12704463"/>
      <inertia ixx="0.0026019" ixy="0.0001226" ixz="7.5e-06" iyy="0.0009202" iyz="-2.4e-06" izz="0.0026365"/>
    </inertial>
    <visual>
      <origin rpy="0 0 0" xyz="0 0 0"/>
      <geometry>
        <mesh filename="package://m2_metal_description/meshes/FR_hip.STL"/>
      </geometry>
      <material name="svan_grey"/>
    </visual>
    <collision>
      <origin rpy="0 0 0" xyz="0 0 0"/>
      <geometry>
        <mesh filename="package://m2_metal_description/meshes/FR_hip.STL"/>
      </geometry>
    </collision>
  </link>
  <!-- hip_joint -->
  <joint name="FR_hip_joint" type="revolute">
    <origin rpy="0 0 0" xyz="0.147 -0.06 0.00025"/>
    <parent link="base"/>
    <child link="FR_hip_link"/>
    <axis xyz="1 0 0"/>
    <limit effort="20" lower="-4.8" upper="4.8" velocity="52.4"/>
  </joint>
  <!-- thigh link -->
  <link name="FR_thigh_link">
    <inertial>
      <origin rpy="0 0 0" xyz="0.0 0.00262472 -0.06933846"/>
      <mass value="0.15396568"/>
      <inertia ixx="0.00075104" ixy="0.0" ixz="0.0" iyy="0.00076325" iyz="-2.968e-05" izz="4.729e-05"/>
    </inertial>
    <visual>
      <origin rpy="0 0 0" xyz="0 0 0"/>
      <geometry>
        <mesh filename="package://m2_metal_description/meshes/FR_thigh.STL"/>
      </geometry>
      <material name="svan_black"/>
    </visual>
    <collision>
      <origin rpy="0 0 0" xyz="0 0 0"/>
      <geometry>
        <mesh filename="package://m2_metal_description/meshes/FR_thigh.STL"/>
      </geometry>
    </collision>
  </link>
  <!-- thigh_joint -->
  <joint name="FR_thigh_joint" type="revolute">
    <origin rpy="0 0 0" xyz="0.043751 -0.0811 0"/>
    <parent link="FR_hip_link"/>
    <child link="FR_thigh_link"/>
    <axis xyz="0 1 0"/>
    <limit effort="55" lower="-4.047197551" upper="4.188790205" velocity="28.6"/>
  </joint>
  <!-- shank_link-->
  <link name="FR_shank_link">
    <inertial>
      <origin rpy="0 0 0" xyz="-0.00106 9e-06 -0.0450013"/>
      <mass value="0.124482"/>
      <inertia ixx="0.0005021" ixy="0.0" ixz="-1.27e-05" iyy="0.0005174" iyz="1e-07" izz="2.02e-05"/>
    </inertial>
    <visual>
      <origin rpy="0 0 0" xyz="0 0 0"/>
      <geometry>
        <mesh filename="package://m2_metal_description/meshes/FR_shank.STL"/>
      </geometry>
      <material name="svan_black"/>
    </visual>
    <collision>
      <origin rpy="0 0 0" xyz="0 0 0"/>
      <geometry>
        <mesh filename="package://m2_metal_description/meshes/FR_shank.STL"/>
      </geometry>
    </collision>
  </link>
  <!-- calf_joint -->
  <joint name="FR_calf_joint" type="revolute">
    <origin rpy="0 0 0" xyz="0 0 -0.1915"/>
    <parent link="FR_thigh_link"/>
    <child link="FR_shank_link"/>
    <axis xyz="0 1 0"/>
    <limit effort="55" lower="-4.696533694" upper="4.916297857" velocity="28.6"/>
  </joint>
  <!-- foot-->
  <link name="foot_FR">
    <contact>
      <friction_anchor/>
      <stiffness value="30000"/>
      <damping value="750"/>
      <spinning_friction value="0.3"/>
      <lateral_friction value="50"/>
    </contact>
    <inertial>
      <origin rpy="0 0 0" xyz="-0.0025566 0.00017773 -0.00416818"/>
      <mass value="0.02330447"/>
      <inertia ixx="2.62e-06" ixy="1e-08" ixz="-3.7e-07" iyy="2.62e-06" iyz="2e-08" izz="3e-06"/>
    </inertial>
    <visual>
      <geometry>
        <mesh filename="package://m2_metal_description/meshes/FL_foot.STL"/>
      </geometry>
    </visual>
    <collision>
      <geometry>
        <mesh filename="package://m2_metal_description/meshes/FL_foot.STL"/>
      </geometry>
    </collision>
  </link>
  <!-- foot_j -->
  <joint name="FR_foot_j" type="revolute">
    <origin rpy="0 0 0" xyz="-0.00351 0 -0.1901"/>
    <parent link="FR_shank_link"/>
    <child link="foot_FR"/>
    <axis xyz="0 0 1"/>
    <limit effort="1000" lower="0" upper="0" velocity="0"/>
  </joint>
  <!-- hip_link-->
  <link name="FL_hip_link">
    <inertial>
      <origin rpy="0 0 0" xyz="0.04244851 0.07733848 0.00084768"/>
      <mass value="1.12704463"/>
      <inertia ixx="0.0026019" ixy="-0.0001226" ixz="7.5e-06" iyy="0.0009202" iyz="2.4e-06" izz="0.0026365"/>
    </inertial>
    <visual>
      <origin rpy="0 0 0" xyz="0 0 0"/>
      <geometry>
        <mesh filename="package://m2_metal_description/meshes/FL_hip.STL"/>
      </geometry>
      <material name="svan_grey"/>
    </visual>
    <collision>
      <origin rpy="0 0 0" xyz="0 0 0"/>
      <geometry>
        <mesh filename="package://m2_metal_description/meshes/FL_hip.STL"/>
      </geometry>
    </collision>
  </link>
  <!-- hip_joint -->
  <joint name="FL_hip_joint" type="revolute">
    <origin rpy="0 0 0" xyz="0.147 0.06 0.00025"/>
    <parent link="base"/>
    <child link="FL_hip_link"/>
    <axis xyz="1 0 0"/>
    <limit effort="20" lower="-4.8" upper="4.8" velocity="52.4"/>
  </joint>
  <!-- thigh link -->
  <link name="FL_thigh_link">
    <inertial>
      <origin rpy="0 0 0" xyz="0.0 -0.00262472 -0.06933846"/>
      <mass value="0.15396568"/>
      <inertia ixx="0.00075104" ixy="-0.0" ixz="0.0" iyy="0.00076325" iyz="2.968e-05" izz="4.729e-05"/>
    </inertial>
    <visual>
      <origin rpy="0 0 0" xyz="0 0 0"/>
      <geometry>
        <mesh filename="package://m2_metal_description/meshes/FL_thigh.STL"/>
      </geometry>
      <material name="svan_black"/>
    </visual>
    <collision>
      <origin rpy="0 0 0" xyz="0 0 0"/>
      <geometry>
        <mesh filename="package://m2_metal_description/meshes/FL_thigh.STL"/>
      </geometry>
    </collision>
  </link>
  <!-- thigh_joint -->
  <joint name="FL_thigh_joint" type="revolute">
    <origin rpy="0 0 0" xyz="0.043751 0.0811 0"/>
    <parent link="FL_hip_link"/>
    <child link="FL_thigh_link"/>
    <axis xyz="0 1 0"/>
    <limit effort="55" lower="-4.047197551" upper="4.188790205" velocity="28.6"/>
  </joint>
  <!-- shank_link-->
  <link name="FL_shank_link">
    <inertial>
      <origin rpy="0 0 0" xyz="-0.00106 -9e-06 -0.0450013"/>
      <mass value="0.124482"/>
      <inertia ixx="0.0005021" ixy="-0.0" ixz="-1.27e-05" iyy="0.0005174" iyz="-1e-07" izz="2.02e-05"/>
    </inertial>
    <visual>
      <origin rpy="0 0 0" xyz="0 0 0"/>
      <geometry>
        <mesh filename="package://m2_metal_description/meshes/FL_shank.STL"/>
      </geometry>
      <material name="svan_black"/>
    </visual>
    <collision>
      <origin rpy="0 0 0" xyz="0 0 0"/>
      <geometry>
        <mesh filename="package://m2_metal_description/meshes/FL_shank.STL"/>
      </geometry>
    </collision>
  </link>
  <!-- calf_joint -->
  <joint name="FL_calf_joint" type="revolute">
    <origin rpy="0 0 0" xyz="0 0 -0.1915"/>
    <parent link="FL_thigh_link"/>
    <child link="FL_shank_link"/>
    <axis xyz="0 1 0"/>
    <limit effort="55" lower="-4.696533694" upper="4.916297857" velocity="28.6"/>
  </joint>
  <!-- foot-->
  <link name="foot_FL">
    <contact>
      <friction_anchor/>
      <stiffness value="30000"/>
      <damping value="750"/>
      <spinning_friction value="0.3"/>
      <lateral_friction value="50"/>
    </contact>
    <inertial>
      <origin rpy="0 0 0" xyz="-0.0025566 -0.00017773 -0.00416818"/>
      <mass value="0.02330447"/>
      <inertia ixx="2.62e-06" ixy="-1e-08" ixz="-3.7e-07" iyy="2.62e-06" iyz="-2e-08" izz="3e-06"/>
    </inertial>
    <visual>
      <geometry>
        <mesh filename="package://m2_metal_description/meshes/FL_foot.STL"/>
      </geometry>
    </visual>
    <collision>
      <geometry>
        <mesh filename="package://m2_metal_description/meshes/FL_foot.STL"/>
      </geometry>
    </collision>
  </link>
  <!-- foot_j -->
  <joint name="FL_foot_j" type="revolute">
    <origin rpy="0 0 0" xyz="-0.00351 0 -0.1901"/>
    <parent link="FL_shank_link"/>
    <child link="foot_FL"/>
    <axis xyz="0 0 1"/>
    <limit effort="1000" lower="0" upper="0" velocity="0"/>
  </joint>
  <!-- hip_link-->
  <link name="RR_hip_link">
    <inertial>
      <origin rpy="0 0 0" xyz="-0.04244851 -0.07733848 0.00084768"/>
      <mass value="1.12704463"/>
      <inertia ixx="0.0026019" ixy="-0.0001226" ixz="-7.5e-06" iyy="0.0009202" iyz="-2.4e-06" izz="0.0026365"/>
    </inertial>
    <visual>
      <origin rpy="3.14159265359 3.14159265359 0" xyz="0 0 0"/>
      <geometry>
        <mesh filename="package://m2_metal_description/meshes/FL_hip.STL"/>
      </geometry>
      <material name="svan_grey"/>
    </visual>
    <collision>
      <origin rpy="3.14159265359 3.14159265359 0" xyz="0 0 0"/>
      <geometry>
        <mesh filename="package://m2_metal_description/meshes/FL_hip.STL"/>
      </geometry>
    </collision>
  </link>
  <!-- hip_joint -->
  <joint name="RR_hip_joint" type="revolute">
    <origin rpy="0 0 0" xyz="-0.147 -0.06 0.00025"/>
    <parent link="base"/>
    <child link="RR_hip_link"/>
    <axis xyz="1 0 0"/>
    <limit effort="20" lower="-4.8" upper="4.8" velocity="52.4"/>
  </joint>
  <!-- thigh link -->
  <link name="RR_thigh_link">
    <inertial>
      <origin rpy="0 0 0" xyz="-0.0 0.00262472 -0.06933846"/>
      <mass value="0.15396568"/>
      <inertia ixx="0.00075104" ixy="-0.0" ixz="-0.0" iyy="0.00076325" iyz="-2.968e-05" izz="4.729e-05"/>
    </inertial>
    <visual>
      <origin rpy="0 0 0" xyz="0 0 0"/>
      <geometry>
        <mesh filename="package://m2_metal_description/meshes/FR_thigh.STL"/>
      </geometry>
      <material name="svan_black"/>
    </visual>
    <collision>
      <origin rpy="0 0 0" xyz="0 0 0"/>
      <geometry>
        <mesh filename="package://m2_metal_description/meshes/FR_thigh.STL"/>
      </geometry>
    </collision>
  </link>
  <!-- thigh_joint -->
  <joint name="RR_thigh_joint" type="revolute">
    <origin rpy="0 0 0" xyz="-0.043751 -0.0811 0"/>
    <parent link="RR_hip_link"/>
    <child link="RR_thigh_link"/>
    <axis xyz="0 1 0"/>
    <limit effort="55" lower="-4.047197551" upper="4.188790205" velocity="28.6"/>
  </joint>
  <!-- shank_link-->
  <link name="RR_shank_link">
    <inertial>
      <origin rpy="0 0 0" xyz="0.00106 9e-06 -0.0450013"/>
      <mass value="0.124482"/>
      <inertia ixx="0.0005021" ixy="0.0" ixz="-1.27e-05" iyy="0.0005174" iyz="1e-07" izz="2.02e-05"/>
    </inertial>
    <visual>
      <origin rpy="0 0 0" xyz="0 0 0"/>
      <geometry>
        <mesh filename="package://m2_metal_description/meshes/FR_shank.STL"/>
      </geometry>
      <material name="svan_black"/>
    </visual>
    <collision>
      <origin rpy="0 0 0" xyz="0 0 0"/>
      <geometry>
        <mesh filename="package://m2_metal_description/meshes/FR_shank.STL"/>
      </geometry>
    </collision>
  </link>
  <!-- calf_joint -->
  <joint name="RR_calf_joint" type="revolute">
    <origin rpy="0 0 0" xyz="0 0 -0.1915"/>
    <parent link="RR_thigh_link"/>
    <child link="RR_shank_link"/>
    <axis xyz="0 1 0"/>
    <limit effort="55" lower="-4.696533694" upper="4.916297857" velocity="28.6"/>
  </joint>
  <!-- foot-->
  <link name="foot_RR">
    <contact>
      <friction_anchor/>
      <stiffness value="30000"/>
      <damping value="750"/>
      <spinning_friction value="0.3"/>
      <lateral_friction value="50"/>
    </contact>
    <inertial>
      <origin rpy="0 0 0" xyz="0.0025566 0.00017773 -0.00416818"/>
      <mass value="0.02330447"/>
      <inertia ixx="2.62e-06" ixy="-1e-08" ixz="3.7e-07" iyy="2.62e-06" iyz="2e-08" izz="3e-06"/>
    </inertial>
    <visual>
      <geometry>
        <mesh filename="package://m2_metal_description/meshes/FL_foot.STL"/>
      </geometry>
    </visual>
    <collision>
      <geometry>
        <mesh filename="package://m2_metal_description/meshes/FL_foot.STL"/>
      </geometry>
    </collision>
  </link>
  <!-- foot_j -->
  <joint name="RR_foot_j" type="revolute">
    <origin rpy="0 0 0" xyz="-0.00351 0 -0.1901"/>
    <parent link="RR_shank_link"/>
    <child link="foot_RR"/>
    <axis xyz="0 0 1"/>
    <limit effort="1000" lower="0" upper="0" velocity="0"/>
  </joint>
  <!-- hip_link-->
  <link name="RL_hip_link">
    <inertial>
      <origin rpy="0 0 0" xyz="-0.04244851 0.07733848 0.00084768"/>
      <mass value="1.12704463"/>
      <inertia ixx="0.0026019" ixy="0.0001226" ixz="-7.5e-06" iyy="0.0009202" iyz="2.4e-06" izz="0.0026365"/>
    </inertial>
    <visual>
      <origin rpy="3.14159265359 3.14159265359 0" xyz="0 0 0"/>
      <geometry>
        <mesh filename="package://m2_metal_description/meshes/FR_hip.STL"/>
      </geometry>
      <material name="svan_grey"/>
    </visual>
    <collision>
      <origin rpy="3.14159265359 3.14159265359 0" xyz="0 0 0"/>
      <geometry>
        <mesh filename="package://m2_metal_description/meshes/FR_hip.STL"/>
      </geometry>
    </collision>
  </link>
  <!-- hip_joint -->
  <joint name="RL_hip_joint" type="revolute">
    <origin rpy="0 0 0" xyz="-0.147 0.06 0.00025"/>
    <parent link="base"/>
    <child link="RL_hip_link"/>
    <axis xyz="1 0 0"/>
    <limit effort="20" lower="-4.8" upper="4.8" velocity="52.4"/>
  </joint>
  <!-- thigh link -->
  <link name="RL_thigh_link">
    <inertial>
      <origin rpy="0 0 0" xyz="-0.0 -0.00262472 -0.06933846"/>
      <mass value="0.15396568"/>
      <inertia ixx="0.00075104" ixy="0.0" ixz="-0.0" iyy="0.00076325" iyz="2.968e-05" izz="4.729e-05"/>
    </inertial>
    <visual>
      <origin rpy="0 0 0" xyz="0 0 0"/>
      <geometry>
        <mesh filename="package://m2_metal_description/meshes/FL_thigh.STL"/>
      </geometry>
      <material name="svan_black"/>
    </visual>
    <collision>
      <origin rpy="0 0 0" xyz="0 0 0"/>
      <geometry>
        <mesh filename="package://m2_metal_description/meshes/FL_thigh.STL"/>
      </geometry>
    </collision>
  </link>
  <!-- thigh_joint -->
  <joint name="RL_thigh_joint" type="revolute">
    <origin rpy="0 0 0" xyz="-0.043751 0.0811 0"/>
    <parent link="RL_hip_link"/>
    <child link="RL_thigh_link"/>
    <axis xyz="0 1 0"/>
    <limit effort="55" lower="-4.047197551" upper="4.188790205" velocity="28.6"/>
  </joint>
  <!-- shank_link-->
  <link name="RL_shank_link">
    <inertial>
      <origin rpy="0 0 0" xyz="0.00106 -9e-06 -0.0450013"/>
      <mass value="0.124482"/>
      <inertia ixx="0.0005021" ixy="-0.0" ixz="-1.27e-05" iyy="0.0005174" iyz="-1e-07" izz="2.02e-05"/>
    </inertial>
    <visual>
      <origin rpy="0 0 0" xyz="0 0 0"/>
      <geometry>
        <mesh filename="package://m2_metal_description/meshes/FL_shank.STL"/>
      </geometry>
      <material name="svan_black"/>
    </visual>
    <collision>
      <origin rpy="0 0 0" xyz="0 0 0"/>
      <geometry>
        <mesh filename="package://m2_metal_description/meshes/FL_shank.STL"/>
      </geometry>
    </collision>
  </link>
  <!-- calf_joint -->
  <joint name="RL_calf_joint" type="revolute">
    <origin rpy="0 0 0" xyz="0 0 -0.1915"/>
    <parent link="RL_thigh_link"/>
    <child link="RL_shank_link"/>
    <axis xyz="0 1 0"/>
    <limit effort="55" lower="-4.696533694" upper="4.916297857" velocity="28.6"/>
  </joint>
  <!-- foot-->
  <link name="foot_RL">
    <contact>
      <friction_anchor/>
      <stiffness value="30000"/>
      <damping value="750"/>
      <spinning_friction value="0.3"/>
      <lateral_friction value="50"/>
    </contact>
    <inertial>
      <origin rpy="0 0 0" xyz="0.0025566 -0.00017773 -0.00416818"/>
      <mass value="0.02330447"/>
      <inertia ixx="2.62e-06" ixy="1e-08" ixz="3.7e-07" iyy="2.62e-06" iyz="-2e-08" izz="3e-06"/>
    </inertial>
    <visual>
      <geometry>
        <mesh filename="package://m2_metal_description/meshes/FL_foot.STL"/>
      </geometry>
    </visual>
    <collision>
      <geometry>
        <mesh filename="package://m2_metal_description/meshes/FL_foot.STL"/>
      </geometry>
    </collision>
  </link>
  <!-- foot_j -->
  <joint name="RL_foot_j" type="revolute">
    <origin rpy="0 0 0" xyz="-0.00351 0 -0.1901"/>
    <parent link="RL_shank_link"/>
    <child link="foot_RL"/>
    <axis xyz="0 0 1"/>
    <limit effort="1000" lower="0" upper="0" velocity="0"/>
  </joint>
  <gazebo>
    <plugin filename="libmotor_controller.so" name="motor_controller">
      <!-- 
            <kp0>75</kp0>
            <kp1>30.2</kp1>
            <kp2>18.415</kp2> -->
      <kp0>200.2</kp0>
      <kp1>60.2</kp1>
      <kp2>42.415</kp2>
      <kd0>1</kd0>
      <kd1>1.5</kd1>
      <kd2>0.5</kd2>
      <!-- 
            <kp0>80</kp0>
            <kp1>40</kp1>
            <kp2>20</kp2>
            <kd0>1</kd0>
            <kd1>1</kd1>
            <kd2>0.5</kd2> -->
      <!-- 
            <kp0>200</kp0>
            <kp1>120</kp1>
            <kp2>60</kp2>
            <kd0>1</kd0>
            <kd1>1</kd1>
            <kd2>0.5</kd2> -->
      <!-- adding higher gains for the swing leg -->
      <kpsw0>300</kpsw0>
      <kpsw1>300</kpsw1>
      <kpsw2>300</kpsw2>
      <kdsw0>6</kdsw0>
      <kdsw1>6</kdsw1>
      <kdsw2>6</kdsw2>
    </plugin>
  </gazebo>
  <!-- IMU sensor -->
  <gazebo>
    <plugin filename="libgazebo_ros_imu.so" name="imu_sensor">
      <alwaysOn>true</alwaysOn>
      <bodyName>base</bodyName>
      <frameName>base</frameName>
      <topicName>/shvan/imu</topicName>
      <serviceName>imu_service</serviceName>
      <xyzOffset> 0 0 0 </xyzOffset>
      <rpyOffset> 0 0 0 </rpyOffset>
      <gaussianNoise>0.001</gaussianNoise>
      <updateRate>1000.0</updateRate>
    </plugin>
  </gazebo>
  <!-- joint and base sensor -->
  <gazebo>
    <plugin filename="libjoint_state_sensor.so" name="joint_state_sensor"/>
  </gazebo>
  <gazebo>
    <plugin filename="libbase_state_sensor.so" name="base_state_sensor"/>
  </gazebo>
  <!-- FR foot -->
  <gazebo reference="foot_FR">
    <material>Gazebo/Black</material>
    <collision>
      <surface>
        <bounce>
          <restitution_coefficient>0</restitution_coefficient>
          <threshold>1e+06</threshold>
        </bounce>
        <friction>
          <torsional>
            <coefficient>0.3</coefficient>
          </torsional>
          <ode>
            <mu>100.0</mu>
            <mu2>50</mu2>
          </ode>
          <bullet>
            <rolling_friction>0.3</rolling_friction>
            <friction2>50</friction2>
          </bullet>
        </friction>
        <contact>
          <bullet>
            <kp>30000.0</kp>
            <kd>1000.0</kd>
          </bullet>
          <ode>
            <kp>30000.0</kp>
            <kd>1000.0</kd>
          </ode>
        </contact>
      </surface>
    </collision>
  </gazebo>
  <!-- FL foot -->
  <gazebo reference="foot_FL">
    <material>Gazebo/Black</material>
    <collision>
      <surface>
        <bounce>
          <restitution_coefficient>0</restitution_coefficient>
          <threshold>1e+06</threshold>
        </bounce>
        <friction>
          <torsional>
            <coefficient>0.3</coefficient>
          </torsional>
          <ode>
            <mu>100.0</mu>
            <mu2>50</mu2>
          </ode>
          <bullet>
            <rolling_friction>0.3</rolling_friction>
            <friction2>50</friction2>
          </bullet>
        </friction>
        <contact>
          <bullet>
            <kp>30000.0</kp>
            <kd>1000.0</kd>
          </bullet>
          <ode>
            <kp>30000.0</kp>
            <kd>1000.0</kd>
          </ode>
        </contact>
      </surface>
    </collision>
  </gazebo>
  <!-- FL foot -->
  <gazebo reference="foot_RL">
    <material>Gazebo/Black</material>
    <collision>
      <surface>
        <bounce>
          <restitution_coefficient>0</restitution_coefficient>
          <threshold>1e+06</threshold>
        </bounce>
        <friction>
          <torsional>
            <coefficient>0.3</coefficient>
          </torsional>
          <ode>
            <mu>100.0</mu>
            <mu2>50</mu2>
          </ode>
          <bullet>
            <rolling_friction>0.3</rolling_friction>
            <friction2>50</friction2>
          </bullet>
        </friction>
        <contact>
          <bullet>
            <kp>30000.0</kp>
            <kd>1000.0</kd>
          </bullet>
          <ode>
            <kp>30000.0</kp>
            <kd>1000.0</kd>
          </ode>
        </contact>
      </surface>
    </collision>
  </gazebo>
  <!-- RR foot -->
  <gazebo reference="foot_RR">
    <material>Gazebo/Black</material>
    <collision>
      <surface>
        <bounce>
          <restitution_coefficient>0</restitution_coefficient>
          <threshold>1e+06</threshold>
        </bounce>
        <friction>
          <torsional>
            <coefficient>0.3</coefficient>
          </torsional>
          <ode>
            <mu>100.0</mu>
            <mu2>50</mu2>
          </ode>
          <bullet>
            <rolling_friction>0.3</rolling_friction>
            <friction2>50</friction2>
          </bullet>
        </friction>
        <contact>
          <bullet>
            <kp>30000.0</kp>
            <kd>1000.0</kd>
          </bullet>
          <ode>
            <kp>30000.0</kp>
            <kd>1000.0</kd>
          </ode>
        </contact>
      </surface>
    </collision>
  </gazebo>
  <!-- Foot contacts. -->
  <!-- <gazebo>
          <plugin name="contact_plugin" filename="libcontact_plugin_new.so">
            <link1>foot_FR</link1>
            <link2>foot_FL</link2>
            <link3>foot_RL</link3>
            <link4>foot_RR</link4>
            <contact_model>0</contact_model>
          </plugin>
      </gazebo> -->
  <gazebo reference="foot_FR">
    <sensor name="FR_contact_sensor" type="contact">
      <always_on>1</always_on>
      <plugin filename="libcontact_plugin_default.so" name="contact_plugin_default">
        <foot_link>FR</foot_link>
      </plugin>
      <contact>
        <collision>foot_FR_collision</collision>
      </contact>
    </sensor>
  </gazebo>
  <gazebo reference="foot_FL">
    <sensor name="FL_contact_sensor" type="contact">
      <always_on>1</always_on>
      <plugin filename="libcontact_plugin_default.so" name="contact_plugin_default">
        <foot_link>FL</foot_link>
      </plugin>
      <contact>
        <collision>foot_FL_collision</collision>
      </contact>
    </sensor>
  </gazebo>
  <gazebo reference="foot_RL">
    <sensor name="RL_contact_sensor" type="contact">
      <always_on>1</always_on>
      <plugin filename="libcontact_plugin_default.so" name="contact_plugin_default">
        <foot_link>RL</foot_link>
      </plugin>
      <contact>
        <collision>foot_RL_collision</collision>
      </contact>
    </sensor>
  </gazebo>
  <gazebo reference="foot_RR">
    <sensor name="RR_contact_sensor" type="contact">
      <always_on>1</always_on>
      <plugin filename="libcontact_plugin_default.so" name="contact_plugin_default">
        <foot_link>RR</foot_link>
      </plugin>
      <contact>
        <collision>foot_RR_collision</collision>
      </contact>
    </sensor>
  </gazebo>
  <!-- <xacro:include filename="$(find m2_metal_description)/xacro/test_d435_camera.urdf.xacro"/> -->
</robot>